Workbook
Name Slicer_Business_Unit: #N/A
Name Slicer_Department: #N/A
Name Slicer_Employee_ID: #N/A
Name Slicer_Employment_Status: #N/A
Name Slicer_Gender: #N/A
Name Slicer_Job_Level: #N/A
Name Slicer_Promotion_Status: #N/A
Name Slicer_Training_Hours: #N/A

Sheet 01_raw_data
A1: 01 - Raw Messy Employee Data
A2: HR extract with extra spaces, mixed cases, missing values, wrong spellings, invalid dates, duplicate IDs, negative values and mapping gaps
A4: Employee ID | B4: Employee Name | C4: Gender | D4: Age | E4: Date of Birth | F4: Department | G4: Business Unit | H4: Designation | I4: Job Level | J4: Manager ID | K4: Manager Name | L4: Location | M4: Country | N4: State | O4: Joining Date | P4: Exit Date | Q4: Employment Status | R4: Salary | S4: Bonus | T4: Performance Rating | U4: Training Hours | V4: Leave Taken | W4: Overtime Hours | X4: Employee Engagement Score | Y4: Promotion Status | Z4: Education Level | AA4: Recruitment Source | AB4: Work Mode | AC4: Cost Center | AD4: Employee Type | AE4: Productivity Score
A5: E0001 | B5: Tess Martin | C5: Male | D5: 56 | E5: 25373 | F5: Data & Analytics | G5: Data & AI | H5: Senior Data Analyst | I5: L6 | J5: M003 | K5: Sarah Lopez | L5: Valencia | M5: Spain | N5: Valencian Community | O5: 44869 | Q5: A | R5: 134000 | S5: 4000 | T5: 2 | U5: 35 | V5: 20 | W5: 10 | X5: 74 | Y5: Not Promoted | Z5: Master's | AA5: University Hiring | AB5: HYBRID | AC5: EU-CC103 | AD5: Contract | AE5: 57.6
A6: E0002 | B6: Miguel Gonzalez | C6: Male | D6: 25 | E6: 37009 | F6: Finance | G6: Corporate Services | H6: Financial Analyst | I6: L4 | J6: M007 | K6: Astrid Bakker | L6: Hamburg | M6: Germany | N6: Hamburg | O6: 43226 | Q6: Active | R6: 107000 | S6: 5400 | T6: 3 | U6: 28 | V6: 15 | W6: 26 | X6: 44 | Y6: Not promoted | Z6: Bachelor's | AA6: Agency | AB6: Hybrid | AC6: EU-CC301 | AD6: Full Time | AE6: 49.4
A7: E0003 | B7: Hannah Wilson | C7: Male | D7: 24 | E7: 37238 | F7: Product | G7: Product & Technology | H7: Product Analyst | I7: L2 | K7: Sophia Moreau | L7: Krakow | M7: poland | N7: Lesser Poland | O7: 45858 | Q7: active | R7: 44000 | S7: 2200 | T7: 3 | U7: 35 | V7: 25 | W7: 16 | X7: 74 | Y7: Not Promoted | Z7: Bachelor's | AA7: Agency | AB7: Remote | AC7: EU-CC102 | AD7: full time | AE7: 63.6
A8: E0004 | B8: Bram Visser | C8: Male | D8: 28 | E8: 12-01-1997 | F8: Legal | G8: risk & compliance | H8: Contracts Analyst | I8: L5 | J8: M011 | K8: Julia Marino | L8: Milan | M8: italy | N8: Lombardy | O8: 44343 | Q8: Active | R8: 118000 | S8: 1200 | T8: 1 | U8: 27 | V8: 20 | W8: 27 | X8: 26 | Y8: Not Promoted | Z8: Bachelor's | AA8: Company Careers Page | AB8: Hybrid | AC8: EU-CC501 | AD8: Contract | AE8: 24.9
A9: E0005 | B9: Kacper Brown | C9: Male | D9: 38 | E9: 32217 | F9: Marketing | G9: Revenue | H9: marketing executive | I9: L6 | J9: M006 | K9: Aleksander Fischer | L9: MADRID | M9: Spain | N9: COMMUNITY OF MADRID | O9: 43996 | Q9: Active | R9: 157000 | S9: 9400 | T9: three | U9: 15 | V9: 12 | W9: 11 | X9: 63 | Y9: Not Promoted | Z9: MBA | AA9: University Hiring | AB9: Hybrid | AC9: EU-CC203 | AD9: FULL-TIME | AE9: 57.3
A10: E0006 | B10: Kacper Gustafsson | C10: Male | D10: 29 | E10: not available | F10: CUSTOMER SUCCESS | G10: Revenue | H10: Client Success Associate | I10: L3 | J10: M054 | K10: Isla Eriksson | L10: Stockholm | M10: Sweden | N10: Stockholm County | O10: 44665 | Q10: A | R10: 79000 | S10: 7100 | T10: 4 | U10: -31 | V10: 23 | W10: 0 | X10: 84 | Y10: Not Promoted | Z10: Bachelor's | AA10: Agency | AB10: Hybrid | AC10: EU-CC202 | AD10: FULL-TIME | AE10: 83.2
A11: E0007 | B11: Ines Martinez | C11: Male | D11: 32 | E11: 34162 | F11: TECH | G11: Product & Technology | H11: Engineering Lead | I11: L3 | J11: M048 | K11: Jack Schmidt | L11: Hamburg | M11: Germany | N11: Hamburg | O11: 45404 | Q11: ACTIVE | R11: 85000 | S11: 1700 | T11: 2 | U11: 57 | V11: 20 | W11: 0 | X11: 46 | Y11: Not Promoted | Z11: Bachelor's | AA11: University Hiring | AB11: hybrid | AC11: EU-CC101 | AD11: Full Time | AE11: 54.1
A12: E0008 | B12: ALESSANDRO JANSEN | C12: Male | D12: 22 | E12: 38098 | F12: Operations | G12: Operations | H12: Workforce Planner | I12: L2 | J12: M010 | K12: Lotte Muller | L12: Eindhvn | M12: NETHERLANDS | N12: North Brabant | O12: 45703 | P12: 01-08-2026 | Q12: Exited | R12: 56000 | S12: 7800 | T12: 5 | U12: 48 | V12: 10 | W12: 1 | X12: 57 | Y12: Not Promoted | Z12: Bachelor's | AA12: European Job Board | AB12: Remote | AC12: EU-CC401 | AD12: full time | AE12: 84.5
A13: E0009 | B13: Javier Ricci | C13: Male | D13: 37 | E13: 32347 | F13: Data & Analytics | G13: Data & AI | H13: Data Scientist | I13: L4 | J13: M020 | K13: Alessandro Lewandowski | L13: Munich | M13: Germany | N13: Bavaria | O13: 42863 | Q13: Active | R13: 109000 | S13: 5400 | T13: 3 | U13: 29 | V13: 18 | W13: 7 | X13: 47 | Y13: Not Promoted | Z13: Diploma | AA13: Company Careers Page | AB13: Hybrid | AC13: EU-CC103 | AD13: Full Time | AE13: 57.2
A14: E0010 | B14: Sophia Petit | C14: Female | D14: 46 | E14: 29087 | F14: Security | G14: risk & compliance | H14: Security Lead | I14: L1 | J14: M056 | K14: Emily Olsson | L14: London | M14: United Kingdom | N14: england | O14: 00/00/0000 | Q14: Active | R14: 49000 | S14: 2400 | T14: 3 | U14: 21 | V14: 2 | W14: 20 | X14: 54 | Y14: Not Promoted | Z14: Bachelor's | AA14: European Job Board | AB14: Office | AC14: EU-CC503 | AD14: Full Time | AE14: 51.1
A15: E0011 | B15: Francesco Ferreira | C15: male | D15: 51 | E15: 27494 | F15: Corp Strategy | G15: Corporate Services | H15: Transformation Lead | I15: L3 | J15: M015 | K15: Lea Ryan | L15: Manchester | M15: United Kingdom | N15: England | O15: 44414 | P15: 45280 | Q15: EXITED | R15: 71000 | S15: 3600 | T15: 3 | U15: 18 | V15: 31 | W15: 0 | X15: 68 | Y15: Not Promoted | Z15: Bachelor's | AA15: LinkedIn | AB15: Remote | AC15: EU-CC303 | AD15: Full Time | AE15: 65.3
A16: E0012 | B16: Emily Fernandes | C16: Female | D16: 24 | E16: 37406 | F16: Rev Ops Unknown | G16: Risk & Compliance | H16: Security Analyst | I16: L2 | J16: M014 | K16: Elena Szymanski | L16: Berlin | M16: Germany | N16: Berlin | O16: 44246 | Q16: Active | R16: 57000 | S16: 2800 | T16: THREE | U16: 12 | V16: 22 | W16: 25 | X16: 57 | Y16: Not Promoted | Z16: Master's | AA16: Indeed | AB16: Remote | AC16: EU-CC503 | AD16: Full Time | AE16: 50
A17: E0013 | B17: Arthur Mulder | C17: Female | D17: 46 | E17: 29183 | F17: Purchasing | G17: Operations | H17: Vendor Manager | I17: L2 | J17: M013 | K17: Ebba Kelly | L17: Stockholm | M17: Sweden | N17: Stockholm County | O17: 44155 | Q17: Active | R17: 66000 | S17: 3300 | T17: 0 | U17: 38 | V17: 17 | W17: 10 | X17: 60 | Y17: Not Promoted | Z17: Master's | AA17: LinkedIn | AB17: Remote | AC17: EU-CC402 | AD17: contract | AE17: 62.5
A18: E0014 | B18: Maximilian Romano | C18: Female | D18: 51 | E18: 27197 | F18: ENGINEERING | G18: product & technology | H18: Platform Engineer | I18: L2 | J18: M051 | K18: Eva Bianchi | L18: MUNICH | M18: Germany | N18: Bavaria | O18: 25/09/2024 | Q18: ACTIVE | R18: 60000 | S18: 5400 | T18: four | U18: 21 | V18: 28 | W18: 13 | X18: 65 | Y18: Not Promoted | Z18: Bachelor's | AA18: European Job Board | AB18: Hybrid | AC18: EU-CC101 | AD18: Full Time | AE18: 67.5
A19: E0015 | B19: Aleksander Brown | C19: female | D19: 42 | E19: 30754 | F19: Customer Success | G19: Revenue | H19: Client Success Associate | I19: L2 | J19: M050 | K19: Louis Szymanski | L19: Munich | M19: GERMANY | N19: Bavaria | O19: 44699 | P19: 45180 | Q19: inactive | R19: 53000 | S19: 4800 | T19: 4 | U19: 24 | V19: 4 | W19: 5 | X19: 52 | Y19: Not Promoted | Z19: Master's | AA19: Employee Referral | AB19: HYBRID | AC19: EU-CC202 | AD19: full time | AE19: 67.7
A20: E0016 | B20: Milan Mulder | C20: Female | D20: 45 | E20: 29509 | F20: Marketing | G20: Revenue | H20: SEO Specialist | I20: L2 | J20: M006 | K20: Aleksander Fischer | L20: Frankfrt | M20: Germany | N20: Hesse | O20: 44325 | Q20: Active | R20: 63000 | S20: 3200 | T20: 3 | U20: 22 | V20: 0 | W20: 9 | X20: 57 | Y20: Not Promoted | Z20: Master's | AA20: Internal Transfer | AB20: hybrid | AC20: EU-CC203 | AD20: Part Time | AE20: 58
A21: E0017 | B21: valeria olsson | C21: Male | D21: 28 | E21: 35861 | F21: Data & Analytics | G21: Data & AI | H21: Analytics Engineer | I21: L2 | J21: M003 | K21: Sarah Lopez | L21: Stockholm | M21: Sweden | N21: stockholm county | O21: 42737 | Q21: active | R21: 64000 | S21: 1300 | T21: 2 | U21: 33 | V21: 9 | W21: 20 | X21: 45 | Y21: Not Promoted | Z21: Bachelor's | AA21: European Job Board | AB21: Hybrid | AC21: EU-CC103 | AD21: part time | AE21: 42
A22: E0018 | B22: Luuk Rodriguez | C22: Male | D22: 26 | E22: 36486 | F22: Customer Success | G22: Revenue | H22: Customer Success Manager | I22: L3 | J22: M024 | K22: Noah Ryan | L22: DUB | M22: Ireland | N22: Leinster | O22: 44684 | Q22: ACTIVE | R22: 72000 | S22: 6500 | T22: 4 | U22: 7 | V22: 7 | W22: 13 | X22: -5 | Y22: Not Promoted | Z22: Bachelor's | AA22: Company Careers Page | AB22: Hybrid | AC22: EU-CC202 | AD22: Full Time | AE22: 70.7
A23: E0019 | B23: Linnea Costa | C23: male | D23: 35 | E23: 07-29-1990 | F23: Product | G23: Product & Technology | H23: PRODUCT MANAGER | I23: L3 | J23: M028 | K23: Sara Fernandes | L23: Dublin | M23: Ireland | N23: Leinster | O23: 42749 | Q23: Active | R23: 85000 | S23: 4200 | T23: 3 | U23: 26 | V23: 25 | W23: 9 | X23: 52 | Y23: Not promoted | Z23: Master's | AA23: Internal Transfer | AB23: WFH | AC23: EU-CC102 | AD23: FULL-TIME | AE23: 57.2
A24: E0020 | B24: Camille Bianchi | C24: Male | D24: 36 | E24: 32707 | F24: Software Engg | G24: Product & Technology | H24: Senior Software Engineer | I24: L2 | J24: M001 | K24: Milan Leroy | L24: London | M24: UNITED KINGDOM | N24: England | O24: 45589 | Q24: ACTIVE | R24: 70000 | S24: 3500 | T24: 3 | U24: 13 | V24: 16 | W24: 6 | X24: 70 | Y24: Not Promoted | Z24: Bachelor's | AA24: European Job Board | AB24: Office | AC24: EU-CC101 | AD24: full time | AE24: 61.8
A25: E0021 | B25: Sofia Costa | C25: Male | D25: 38 | E25: 32295 | F25: ENGINEERING | G25: PRODUCT & TECHNOLOGY | H25: Platform Engineer | I25: L6 | J25: M048 | K25: Jack Schmidt | L25: REMOTE | M25: Europe | N25: Remote | O25: 45988 | Q25: A | R25: 149000 | S25: 14900 | T25: 4 | U25: 6 | V25: 16 | W25: 16 | X25: 65 | Y25: Not promoted | Z25: Master's | AA25: European Job Board | AB25: Remote | AC25: EU-CC101 | AD25: Full Time | AE25: 62.2
A26: E0022 | B26: Marco Wisniewski | C26: M | D26: 28 | E26: 1998/03/24 | F26: Commercial | G26: Revenue | H26: Enterprise Account Manager | I26: L4 | J26: M026 | K26: Sergio Rodrigues | L26: WROCLAW | M26: Poland | N26: Lower Silesian | O26: 44776 | Q26: active | R26: 68000 | S26: 9500 | T26: 5 | U26: 12 | V26: 19 | W26: 25 | X26: 72 | Y26: Not Promoted | Z26: Bachelor's | AA26: University Hiring | AB26: Hybrid | AC26: EU-CC201 | AD26: Full Time | AE26: 73.2
A27: E0023 | B27: Manuel Murphy | C27: Male | D27: 25 | E27: 36952 | F27: Data & Analytics | G27: Data & AI | H27: Analytics Engineer | I27: L2 | J27: M058 | K27: Lukas Esposito | L27: BRU | M27: Belgium | N27: Brussels-Capital | O27: 44582 | Q27: ACTIVE | R27: 52000 | S27: -1000 | T27: 2 | U27: 9 | V27: 12 | W27: 35 | X27: 75 | Y27: Not Promoted | Z27: MBA | AA27: European Job Board | AB27: Work From Home | AC27: EU-CC103 | AD27: FTE | AE27: 46.5
A28: E0024 | B28: Laura Fernandez | C28: Female | D28: 40 | E28: 31317 | F28: Human Resources | G28: Corporate Services | H28: People Operations Analyst | I28: L3 | J28: M060 | K28: Matteo Wagner | L28: BER | M28: Germany | N28: Berlin | O28: 44749 | Q28: Active | R28: 80000 | S28: 7200 | T28: 4 | U28: 30 | V28: 10 | W28: 14 | X28: 57 | Y28: Not Promoted | Z28: Bachelor's | AA28: LinkedIn | AB28: Hybrid | AC28: EU-CC302 | AD28: Full Time | AE28: 66.5
A29: E0025 | B29: Elsa Eriksson | C29: Non-Binary | D29: 53 | E29: 26753 | F29: Customer Success | G29: Revenue | H29: Client Success Associate | I29: L3 | J29: M054 | K29: Isla Eriksson | L29: Lyon | M29: France | N29: AUVERGNE-RHONE-ALPES | O29: 2020/04/23 | Q29: Active | R29: 71000 | S29: 6400 | T29: 4 | U29: 15 | V29: 18 | W29: 0 | X29: 76 | Y29: Not Promoted | Z29: PhD | AA29: Indeed | AB29: hybrid | AC29: EU-CC202 | AD29: Full Time | AE29: 76.3
A30: E0026 | B30: Sergio Larsson | C30: Male | D30: 28 | E30: 35735 | F30: TECH | G30: Product & Technology | H30: Software Engineer | I30: L5 | J30: M051 | K30: Eva Bianchi | L30: Dublin | M30: Ireland | N30: Leinster | O30: 2024/03/03 | Q30: Actve | R30: 167000 | S30: 10000 | T30: 3 | U30: 17 | V30: 5 | W30: 22 | X30: 43 | Y30: no | Z30: Master's | AA30: Company Careers Page | AB30: remote | AC30: EU-CC101 | AD30: Full Time | AE30: 46.3
A31: E0027 | B31: Hugo Gomez | C31: Male | D31: 26 | E31: 36571 | F31: Finance | G31: Corporate Services | H31: Finance Manager | I31: L5 | J31: M007 | K31: Astrid Bakker | L31: Lyon | M31: France | N31: Auvergne-Rhone-Alpes | O31: 43062 | Q31: Active | R31: 131000 | S31: 13100 | T31: 4 | U31: 27 | V31: 13 | W31: 14 | X31: 60 | Y31: Not promoted | Z31: Bachelor's | AA31: Company Careers Page | AB31: hybrid | AC31: EU-CC301 | AD31: full time | AE31: 66.8
A32: E0028 | B32: Gabriel Dubois | C32: Male | D32: 46 | E32: 29069 | F32: HUMAN RESOURCES | G32: Corporate Services | H32: Talent Acquisition Specialist | I32: L3 | J32: M033 | K32: Pieter Perez | L32: LILLE | M32: France | N32: Hauts-de-France | O32: 43607 | P32: 45602 | Q32: inactive | R32: 79000 | S32: 1600 | T32: 2 | U32: -14 | V32: 22 | W32: 5 | X32: 41 | Y32: no | Z32: BACHELOR'S | AA32: Internal Transfer | AB32: On-site | AC32: EU-CC302 | AD32: Full Time | AE32: 43.4
A33: E0029 | B33: Diego Fischer | C33: Male | D33: 58 | E33: 24820 | F33: Marketing | G33: REVENUE | H33: Content Specialist | I33: L7 | J33: M006 | K33: Aleksander Fischer | L33: Remote - Europe | M33: Europe | N33: Remote | O33: 45047 | Q33: Active | R33: 233000 | S33: 23300 | T33: 4 | U33: 39 | V33: 17 | W33: 0 | X33: 72 | Y33: NO | Z33: Master's | AA33: Agency | AB33: Office | AC33: EU-CC203 | AD33: full time | AE33: 81
A34: E0030 | B34: Luuk Byrne | C34: Female | D34: 30 | E34: 34909 | F34: ENGINERING | G34: Product & Technology | H34: Software Engineer | I34: L3 | J34: M039 | K34: Freya Martinez | L34: KRAKOW | M34: poland | N34: lesser poland | O34: 42545 | Q34: Active | R34: 60000 | S34: 3000 | T34: 3 | U34: 17 | V34: 17 | W34: 16 | X34: 39 | Y34: Not Promoted | Z34: Bachelor's | AA34: Internal Transfer | AB34: Remote | AC34: EU-CC101 | AD34: Full Time | AE34: 46.9
A35: E0023 | B35: Diego De Jong | C35: Female | D35: 43 | E35: 30423 | F35: Customer Success | G35: Revenue | H35: Support Specialist | I35: L1 | J35: M054 | K35: Isla Eriksson | L35: Remote - Europe | M35: Europe | N35: Remote | O35: 45446 | Q35: Active | R35: 32000 | S35: 1600 | T35: 3 | U35: 6 | V35: 17 | W35: 6 | X35: 51 | Y35: Not Promoted | Z35: Master's | AA35: Agency | AB35: On-site | AC35: EU-CC202 | AD35: FTE | AE35: 53.3
A36: E0032 | B36: Arthur Gustafsson | C36: F | D36: 57 | E36: 25201 | F36: Purchasing | G36: Operations | H36: Procurement Analyst | I36: L2 | J36: M049 | K36: Marco Gonzalez | L36: MILAN | M36: Italy | N36: LOMBARDY | O36: 45798 | Q36: Active | R36: 45000 | S36: 6300 | T36: 5 | U36: 19 | V36: 22 | W36: 27 | X36: 88 | Y36: Promoted | Z36: Bachelor's | AA36: Company Careers Page | AB36: hybrid | AC36: EU-CC402 | AD36: Full Time | AE36: 80.5
A37: E0033 | B37: Leonardo Walsh | C37: Male | D37: 53 | E37: 26514 | F37: Commercial | G37: Revenue | H37: Account Executive | I37: L6 | J37: M023 | K37: Alice Greco | L37: BERLIN | M37: Germany | N37: berlin | O37: 44314 | Q37: active | R37: 204000 | S37: 12200 | T37: 3 | U37: 38 | V37: 9 | W37: 18 | X37: 66 | Y37: Not Promoted | Z37: mba | AA37: European Job Board | AB37: ONSITE | AC37: EU-CC201 | AD37: Full Time | AE37: 60.6
A38: E0034 | B38: alice taylor | C38: Male | D38: 43 | E38: 30357 | F38: Corp Strategy | G38: corporate services | H38: Business Analyst | I38: L4 | J38: M015 | K38: Lea Ryan | L38: MILAN | M38: Italy | N38: lombardy | O38: 44841 | Q38: Active | R38: 88000 | S38: 7900 | T38: 4 | U38: 27 | V38: 5 | W38: 7 | X38: 98 | Y38: Not Promoted | Z38: Bachelor's | AA38: Indeed | AB38: Office | AC38: EU-CC303 | AD38: Contract | AE38: 83.5
A39: E0035 | B39: Sofia Jones | C39: Male | D39: 37 | E39: 32372 | F39: Sale | G39: Revenue | H39: Account Executive | I39: L2 | J39: M016 | K39: Juliette Williams | L39: Londoon | M39: Poland | N39: Masovian | O39: 44898 | Q39: Active | R39: 45000 | S39: 2200 | T39: 6 | U39: 35 | V39: 20 | W39: 14 | X39: 62 | Y39: Not Promoted | Z39: MASTER'S | AA39: Internal Transfer | AB39: Hybrid | AC39: EU-CC201 | AD39: part time | AE39: 60.5
A40: E0036 | B40: Sophia Rodriguez | C40: F | D40: 49 | E40: 2026-15-09 | F40: ENGINEERING | G40: Product & Technology | H40: frontend engineer | I40: L4 | J40: M001 | K40: Milan Leroy | L40: Brussels | M40: Belgium | N40: Brussels-Capital | O40: 43893 | Q40: ACTIVE | R40: 109000 | S40: 5400 | T40: 3 | U40: 21 | V40: 8 | W40: 5 | X40: 59 | Y40: Not Promoted | Z40: bachelor's | AA40: Company Careers Page | AB40: Office | AC40: EU-CC101 | AD40: Full Time | AE40: 60.4
A41: E0037 | B41: Oscar Ferreira | C41: Female | D41: 49 | E41: 28059 | F41: Compliance | G41: Risk & Compliance | H41: Regulatory Specialist | I41: L3 | J41: M025 | K41: Elias De Jong | L41: Paris | M41: France | N41: Ile-de-France | O41: 42927 | Q41: Active | R41: 79000 | S41: 1600 | T41: 2 | U41: 27 | V41: 13 | W41: 13 | X41: 53 | Y41: Not Promoted | Z41: Diploma | AA41: Agency | AB41: remote | AC41: EU-CC502 | AD41: FTE | AE41: 46.8
...

Sheet 01_clean_data
A1: Employee ID | B1: Employee Name | C1: Gender | D1: Age | E1: Date of Birth | F1: DOB FLAGS | G1: Department | H1: Business Unit | I1: Designation | J1: Job Level | K1: Manager ID | L1: Manager Name | M1: Location | N1: Country | O1: State | P1: Joining Date | Q1: Exit Date | R1: Employment Status | S1: Salary | T1: Bonus | U1: Performance Rating | V1: Training Hours | W1: Leave Taken | X1: Overtime Hours | Y1: Employee Engagement Score | Z1: Promotion Status | AA1: Education Level | AB1: Recruitment Source | AC1: Work Mode | AD1: Cost Center | AE1: Employee Type | AF1: Productivity Score
A2: ="E"&TEXT(VALUE(SUBSTITUTE(UPPER(TRIM('01_raw_data'!A5)),"E","")),"0000") -> E0001 | B2: =IF('01_raw_data'!B5="", "", PROPER(TRIM('01_raw_data'!B5))) -> Tess Martin | C2: =_xlfn.XLOOKUP(PROPER(TRIM('01_raw_data'!C5)),'03_lookups'!$A$4:$A$9,'03_lookups'!$B$4:$B$9,"Needs Review") -> Male | D2: =VALUE('01_raw_data'!D5) -> 56 | E2: =IF(OR('01_raw_data'!E5="", LOWER(TRIM('01_raw_data'!E5))="not available"), "Missing", '01_raw_data'!E5) -> 25373 | F2: =IF(OR(E2="",LOWER(TRIM(E2))="not available"),"Missing",IF(ISNUMBER(E2),"Valid","Needs Review")) -> Valid | G2: =_xlfn.XLOOKUP(UPPER(TRIM('01_raw_data'!F5)),'04_departments'!A5:A60,'04_departments'!C5:C60,"Needs Review") -> Data & Analytics | H2: =_xlfn.XLOOKUP('01_clean_data'!G2, '04_departments'!$C$5:$C$60,'04_departments'!$D$5:$D$60,"Needs Review") -> Data & AI | I2: =PROPER(TRIM('01_raw_data'!H5)) -> Senior Data Analyst | J2: =IFERROR(UPPER('01_raw_data'!I5), "") -> L6 | K2: =IFERROR(UPPER('01_raw_data'!J5), "") -> M003 | L2: =IFERROR(VLOOKUP(K2,'05_manager_mapping'!$A$5:$B$64,2), "Missing") -> Sarah Lopez | M2: =IFERROR(_xlfn.XLOOKUP('01_raw_data'!L5,'06_location_master'!$B$5:$B$60,'06_location_master'!$C$5:$C$60), "Missing Location") -> Valencia | N2: =IFERROR(_xlfn.XLOOKUP(M2,'06_location_master'!$C$5:$C$60,'06_location_master'!$D$5:$D$60), "Missing Country") -> Spain | O2: =IFERROR(_xlfn.XLOOKUP(M2,'06_location_master'!$C$5:$C$60,'06_location_master'!$E$5:$E$60), "Missing State") -> Valencian Community | P2: =IFERROR(--'01_raw_data'!O5,"Missing Date") -> 44869 | Q2: =IF(TRIM('01_raw_data'!P5)="","", IFERROR('01_raw_data'!P5, "check")) | R2: =IFERROR(IF(OR(UPPER(TRIM('01_raw_data'!Q5))="A",UPPER(TRIM('01_raw_data'!Q5)="ACTVE"),UPPER(TRIM('01_raw_data'!Q5))="ACTIVE"), "Active", IF(OR(UPPER(TRIM('01_raw_data'!Q5)="INACTIVE"),UPPER(TRIM('01_raw_data'!Q5))="INACTVE"),"Inactive",IF(OR(UPPER(TRIM('01_raw_data'!Q5))="EXITED"), "Exited", IF(OR(UPPER(TRIM('01_raw_data'!Q5))="TERMINATED"), "Terminated", IF(OR(UPPER(TRIM('01_raw_data'!Q5))="LEFT"),"Left",IF(OR(UPPER(TRIM('01_raw_data'!Q5))="RESIGNED"),"Resigned")))))),"Check") -> Active | S2: =IFERROR(IF(VALUE('01_raw_data'!R5)>0,VALUE('01_raw_data'!R5),"Check"),"Check") -> 134000 | T2: =IFERROR(IF(VALUE('01_raw_data'!S5)>0, VALUE('01_raw_data'!S5), "Check"), "Check") -> 4000 | U2: =IFERROR(VLOOKUP(UPPER(TRIM('01_raw_data'!T5)),'07_performance_master'!$A$5:$B$14,2,FALSE),"Check") -> 2 | V2: =IFERROR(IF(VALUE('01_raw_data'!U5)>0,VALUE('01_raw_data'!U5),"Check"),"Check") -> 35 | W2: =IFERROR(IF(VALUE('01_raw_data'!V5)>=0, VALUE('01_raw_data'!V5), "Check"), "Check") -> 20 | X2: =IFERROR(IF(VALUE('01_raw_data'!W5)>=0, VALUE('01_raw_data'!W5),"Check"), "Check") -> 10 | Y2: =IFERROR(IF(AND(VALUE('01_raw_data'!X5)>=0, VALUE('01_raw_data'!X5)<=100), VALUE('01_raw_data'!X5), "Check"), "Check") -> 74 | Z2: =IFERROR(IF(OR(UPPER(TRIM('01_raw_data'!Y5))="YES", UPPER(TRIM('01_raw_data'!Y5))="PROMOTED"),"Promoted", IF(OR(UPPER(TRIM('01_raw_data'!Y5))="NO",UPPER(TRIM('01_raw_data'!Y5))="NOT PROMOTED"), "Not Promoted", "Check")),"Check") -> Not Promoted | AA2: =IFERROR(PROPER(TRIM('01_raw_data'!Z5)), "") -> Master'S | AB2: =IFERROR(PROPER(TRIM('01_raw_data'!AA5)),"") -> University Hiring | AC2: =IFERROR(IF(UPPER(TRIM('01_raw_data'!AB5))="HYBRID","Hybrid",IF(OR(UPPER(TRIM('01_raw_data'!AB5))="REMOTE",UPPER(TRIM('01_raw_data'!AB5))="WFH",UPPER(TRIM('01_raw_data'!AB5))="WORK FROM HOME"),"Remote",IF(OR(UPPER(TRIM('01_raw_data'!AB5))="ONSITE",UPPER(TRIM('01_raw_data'!AB5))="ON-SITE",UPPER(TRIM('01_raw_data'!AB5))="OFFICE"),"Office"))),"Check") -> Hybrid | AD2: =IFERROR(VLOOKUP(UPPER(TRIM('01_raw_data'!AC5)),'09_cost_center'!$A$5:$E$19,1,FALSE), "Check") -> EU-CC103 | AE2: =IFERROR(IF(OR(UPPER(TRIM('01_raw_data'!AD5))="CONTRACT", UPPER(TRIM('01_raw_data'!AD5))="CONTRACTOR"), "Contract", IF(OR(PROPER(TRIM('01_raw_data'!AD5))="FTE", UPPER(TRIM('01_raw_data'!AD5))="FULL TIME", UPPER(TRIM('01_raw_data'!AD5))="FULL-TIME"), "Full Time", IF(OR(UPPER(TRIM('01_raw_data'!AD5))="INTERN", UPPER(TRIM('01_raw_data'!AD5))="INTERNSHIP"), "Intern", IF(OR(UPPER(TRIM('01_raw_data'!AD5))="PART TIME", UPPER(TRIM('01_raw_data'!AD5))="PART-TIME"), "Part Time")))), "Check") -> Contract | AF2: =IFERROR(IF(AND(VALUE('01_raw_data'!AE5)>=0,VALUE('01_raw_data'!AE5)<=100), VALUE('01_raw_data'!AE5), "Check"), "Check") -> 57.6
A3: ="E"&TEXT(VALUE(SUBSTITUTE(UPPER(TRIM('01_raw_data'!A6)),"E","")),"0000") -> E0002 | B3: =IF('01_raw_data'!B6="", "", PROPER(TRIM('01_raw_data'!B6))) -> Miguel Gonzalez | C3: =_xlfn.XLOOKUP(PROPER(TRIM('01_raw_data'!C6)),'03_lookups'!$A$4:$A$9,'03_lookups'!$B$4:$B$9,"Needs Review") -> Male | D3: =VALUE('01_raw_data'!D6) -> 25 | E3: =IF(OR('01_raw_data'!E6="", LOWER(TRIM('01_raw_data'!E6))="not available"), "Missing", '01_raw_data'!E6) -> 37009 | F3: =IF(OR(E3="",LOWER(TRIM(E3))="not available"),"Missing",IF(ISNUMBER(E3),"Valid","Needs Review")) -> Valid | G3: =_xlfn.XLOOKUP(UPPER(TRIM('01_raw_data'!F6)),'04_departments'!A6:A61,'04_departments'!C6:C61,"Needs Review") -> Finance | H3: =_xlfn.XLOOKUP('01_clean_data'!G3, '04_departments'!$C$5:$C$60,'04_departments'!$D$5:$D$60,"Needs Review") -> Corporate Services | I3: =PROPER(TRIM('01_raw_data'!H6)) -> Financial Analyst | J3: =IFERROR(UPPER('01_raw_data'!I6), "") -> L4 | K3: =IFERROR(UPPER('01_raw_data'!J6), "") -> M007 | L3: =IFERROR(VLOOKUP(K3,'05_manager_mapping'!$A$5:$B$64,2), "Missing") -> Astrid Bakker | M3: =IFERROR(_xlfn.XLOOKUP('01_raw_data'!L6,'06_location_master'!$B$5:$B$60,'06_location_master'!$C$5:$C$60), "Missing Location") -> Hamburg | N3: =IFERROR(_xlfn.XLOOKUP(M3,'06_location_master'!$C$5:$C$60,'06_location_master'!$D$5:$D$60), "Missing Country") -> Germany | O3: =IFERROR(_xlfn.XLOOKUP(M3,'06_location_master'!$C$5:$C$60,'06_location_master'!$E$5:$E$60), "Missing State") -> Hamburg | P3: =IFERROR(--'01_raw_data'!O6,"Missing Date") -> 43226 | Q3: =IF(TRIM('01_raw_data'!P6)="","", IFERROR('01_raw_data'!P6, "check")) | R3: =IFERROR(IF(OR(UPPER(TRIM('01_raw_data'!Q6))="A",UPPER(TRIM('01_raw_data'!Q6)="ACTVE"),UPPER(TRIM('01_raw_data'!Q6))="ACTIVE"), "Active", IF(OR(UPPER(TRIM('01_raw_data'!Q6)="INACTIVE"),UPPER(TRIM('01_raw_data'!Q6))="INACTVE"),"Inactive",IF(OR(UPPER(TRIM('01_raw_data'!Q6))="EXITED"), "Exited", IF(OR(UPPER(TRIM('01_raw_data'!Q6))="TERMINATED"), "Terminated", IF(OR(UPPER(TRIM('01_raw_data'!Q6))="LEFT"),"Left",IF(OR(UPPER(TRIM('01_raw_data'!Q6))="RESIGNED"),"Resigned")))))),"Check") -> Active | S3: =IFERROR(IF(VALUE('01_raw_data'!R6)>0,VALUE('01_raw_data'!R6),"Check"),"Check") -> 107000 | T3: =IFERROR(IF(VALUE('01_raw_data'!S6)>0, VALUE('01_raw_data'!S6), "Check"), "Check") -> 5400 | U3: =IFERROR(VLOOKUP(UPPER(TRIM('01_raw_data'!T6)),'07_performance_master'!$A$5:$B$14,2,FALSE),"Check") -> 3 | V3: =IFERROR(IF(VALUE('01_raw_data'!U6)>0,VALUE('01_raw_data'!U6),"Check"),"Check") -> 28 | W3: =IFERROR(IF(VALUE('01_raw_data'!V6)>=0, VALUE('01_raw_data'!V6), "Check"), "Check") -> 15 | X3: =IFERROR(IF(VALUE('01_raw_data'!W6)>=0, VALUE('01_raw_data'!W6),"Check"), "Check") -> 26 | Y3: =IFERROR(IF(AND(VALUE('01_raw_data'!X6)>=0, VALUE('01_raw_data'!X6)<=100), VALUE('01_raw_data'!X6), "Check"), "Check") -> 44 | Z3: =IFERROR(IF(OR(UPPER(TRIM('01_raw_data'!Y6))="YES", UPPER(TRIM('01_raw_data'!Y6))="PROMOTED"),"Promoted", IF(OR(UPPER(TRIM('01_raw_data'!Y6))="NO",UPPER(TRIM('01_raw_data'!Y6))="NOT PROMOTED"), "Not Promoted", "Check")),"Check") -> Not Promoted | AA3: =IFERROR(PROPER(TRIM('01_raw_data'!Z6)), "") -> Bachelor'S | AB3: =IFERROR(PROPER(TRIM('01_raw_data'!AA6)),"") -> Agency | AC3: =IFERROR(IF(UPPER(TRIM('01_raw_data'!AB6))="HYBRID","Hybrid",IF(OR(UPPER(TRIM('01_raw_data'!AB6))="REMOTE",UPPER(TRIM('01_raw_data'!AB6))="WFH",UPPER(TRIM('01_raw_data'!AB6))="WORK FROM HOME"),"Remote",IF(OR(UPPER(TRIM('01_raw_data'!AB6))="ONSITE",UPPER(TRIM('01_raw_data'!AB6))="ON-SITE",UPPER(TRIM('01_raw_data'!AB6))="OFFICE"),"Office"))),"Check") -> Hybrid | AD3: =IFERROR(VLOOKUP(UPPER(TRIM('01_raw_data'!AC6)),'09_cost_center'!$A$5:$E$19,1,FALSE), "Check") -> EU-CC301 | AE3: =IFERROR(IF(OR(UPPER(TRIM('01_raw_data'!AD6))="CONTRACT", UPPER(TRIM('01_raw_data'!AD6))="CONTRACTOR"), "Contract", IF(OR(PROPER(TRIM('01_raw_data'!AD6))="FTE", UPPER(TRIM('01_raw_data'!AD6))="FULL TIME", UPPER(TRIM('01_raw_data'!AD6))="FULL-TIME"), "Full Time", IF(OR(UPPER(TRIM('01_raw_data'!AD6))="INTERN", UPPER(TRIM('01_raw_data'!AD6))="INTERNSHIP"), "Intern", IF(OR(UPPER(TRIM('01_raw_data'!AD6))="PART TIME", UPPER(TRIM('01_raw_data'!AD6))="PART-TIME"), "Part Time")))), "Check") -> Full Time | AF3: =IFERROR(IF(AND(VALUE('01_raw_data'!AE6)>=0,VALUE('01_raw_data'!AE6)<=100), VALUE('01_raw_data'!AE6), "Check"), "Check") -> 49.4
A4: ="E"&TEXT(VALUE(SUBSTITUTE(UPPER(TRIM('01_raw_data'!A7)),"E","")),"0000") -> E0003 | B4: =IF('01_raw_data'!B7="", "", PROPER(TRIM('01_raw_data'!B7))) -> Hannah Wilson | C4: =_xlfn.XLOOKUP(PROPER(TRIM('01_raw_data'!C7)),'03_lookups'!$A$4:$A$9,'03_lookups'!$B$4:$B$9,"Needs Review") -> Male | D4: =VALUE('01_raw_data'!D7) -> 24 | E4: =IF(OR('01_raw_data'!E7="", LOWER(TRIM('01_raw_data'!E7))="not available"), "Missing", '01_raw_data'!E7) -> 37238 | F4: =IF(OR(E4="",LOWER(TRIM(E4))="not available"),"Missing",IF(ISNUMBER(E4),"Valid","Needs Review")) -> Valid | G4: =_xlfn.XLOOKUP(UPPER(TRIM('01_raw_data'!F7)),'04_departments'!A7:A62,'04_departments'!C7:C62,"Needs Review") -> Product | H4: =_xlfn.XLOOKUP('01_clean_data'!G4, '04_departments'!$C$5:$C$60,'04_departments'!$D$5:$D$60,"Needs Review") -> Product & Technology | I4: =PROPER(TRIM('01_raw_data'!H7)) -> Product Analyst | J4: =IFERROR(UPPER('01_raw_data'!I7), "") -> L2 | K4: =IFERROR(UPPER('01_raw_data'!J7), "") | L4: =IFERROR(VLOOKUP(K4,'05_manager_mapping'!$A$5:$B$64,2), "Missing") -> Missing | M4: =IFERROR(_xlfn.XLOOKUP('01_raw_data'!L7,'06_location_master'!$B$5:$B$60,'06_location_master'!$C$5:$C$60), "Missing Location") -> Krakow | N4: =IFERROR(_xlfn.XLOOKUP(M4,'06_location_master'!$C$5:$C$60,'06_location_master'!$D$5:$D$60), "Missing Country") -> Poland | O4: =IFERROR(_xlfn.XLOOKUP(M4,'06_location_master'!$C$5:$C$60,'06_location_master'!$E$5:$E$60), "Missing State") -> Lesser Poland | P4: =IFERROR(--'01_raw_data'!O7,"Missing Date") -> 45858 | Q4: =IF(TRIM('01_raw_data'!P7)="","", IFERROR('01_raw_data'!P7, "check")) | R4: =IFERROR(IF(OR(UPPER(TRIM('01_raw_data'!Q7))="A",UPPER(TRIM('01_raw_data'!Q7)="ACTVE"),UPPER(TRIM('01_raw_data'!Q7))="ACTIVE"), "Active", IF(OR(UPPER(TRIM('01_raw_data'!Q7)="INACTIVE"),UPPER(TRIM('01_raw_data'!Q7))="INACTVE"),"Inactive",IF(OR(UPPER(TRIM('01_raw_data'!Q7))="EXITED"), "Exited", IF(OR(UPPER(TRIM('01_raw_data'!Q7))="TERMINATED"), "Terminated", IF(OR(UPPER(TRIM('01_raw_data'!Q7))="LEFT"),"Left",IF(OR(UPPER(TRIM('01_raw_data'!Q7))="RESIGNED"),"Resigned")))))),"Check") -> Active | S4: =IFERROR(IF(VALUE('01_raw_data'!R7)>0,VALUE('01_raw_data'!R7),"Check"),"Check") -> 44000 | T4: =IFERROR(IF(VALUE('01_raw_data'!S7)>0, VALUE('01_raw_data'!S7), "Check"), "Check") -> 2200 | U4: =IFERROR(VLOOKUP(UPPER(TRIM('01_raw_data'!T7)),'07_performance_master'!$A$5:$B$14,2,FALSE),"Check") -> 3 | V4: =IFERROR(IF(VALUE('01_raw_data'!U7)>0,VALUE('01_raw_data'!U7),"Check"),"Check") -> 35 | W4: =IFERROR(IF(VALUE('01_raw_data'!V7)>=0, VALUE('01_raw_data'!V7), "Check"), "Check") -> 25 | X4: =IFERROR(IF(VALUE('01_raw_data'!W7)>=0, VALUE('01_raw_data'!W7),"Check"), "Check") -> 16 | Y4: =IFERROR(IF(AND(VALUE('01_raw_data'!X7)>=0, VALUE('01_raw_data'!X7)<=100), VALUE('01_raw_data'!X7), "Check"), "Check") -> 74 | Z4: =IFERROR(IF(OR(UPPER(TRIM('01_raw_data'!Y7))="YES", UPPER(TRIM('01_raw_data'!Y7))="PROMOTED"),"Promoted", IF(OR(UPPER(TRIM('01_raw_data'!Y7))="NO",UPPER(TRIM('01_raw_data'!Y7))="NOT PROMOTED"), "Not Promoted", "Check")),"Check") -> Not Promoted | AA4: =IFERROR(PROPER(TRIM('01_raw_data'!Z7)), "") -> Bachelor'S | AB4: =IFERROR(PROPER(TRIM('01_raw_data'!AA7)),"") -> Agency | AC4: =IFERROR(IF(UPPER(TRIM('01_raw_data'!AB7))="HYBRID","Hybrid",IF(OR(UPPER(TRIM('01_raw_data'!AB7))="REMOTE",UPPER(TRIM('01_raw_data'!AB7))="WFH",UPPER(TRIM('01_raw_data'!AB7))="WORK FROM HOME"),"Remote",IF(OR(UPPER(TRIM('01_raw_data'!AB7))="ONSITE",UPPER(TRIM('01_raw_data'!AB7))="ON-SITE",UPPER(TRIM('01_raw_data'!AB7))="OFFICE"),"Office"))),"Check") -> Remote | AD4: =IFERROR(VLOOKUP(UPPER(TRIM('01_raw_data'!AC7)),'09_cost_center'!$A$5:$E$19,1,FALSE), "Check") -> EU-CC102 | AE4: =IFERROR(IF(OR(UPPER(TRIM('01_raw_data'!AD7))="CONTRACT", UPPER(TRIM('01_raw_data'!AD7))="CONTRACTOR"), "Contract", IF(OR(PROPER(TRIM('01_raw_data'!AD7))="FTE", UPPER(TRIM('01_raw_data'!AD7))="FULL TIME", UPPER(TRIM('01_raw_data'!AD7))="FULL-TIME"), "Full Time", IF(OR(UPPER(TRIM('01_raw_data'!AD7))="INTERN", UPPER(TRIM('01_raw_data'!AD7))="INTERNSHIP"), "Intern", IF(OR(UPPER(TRIM('01_raw_data'!AD7))="PART TIME", UPPER(TRIM('01_raw_data'!AD7))="PART-TIME"), "Part Time")))), "Check") -> Full Time | AF4: =IFERROR(IF(AND(VALUE('01_raw_data'!AE7)>=0,VALUE('01_raw_data'!AE7)<=100), VALUE('01_raw_data'!AE7), "Check"), "Check") -> 63.6
A5: ="E"&TEXT(VALUE(SUBSTITUTE(UPPER(TRIM('01_raw_data'!A8)),"E","")),"0000") -> E0004 | B5: =IF('01_raw_data'!B8="", "", PROPER(TRIM('01_raw_data'!B8))) -> Bram Visser | C5: =_xlfn.XLOOKUP(PROPER(TRIM('01_raw_data'!C8)),'03_lookups'!$A$4:$A$9,'03_lookups'!$B$4:$B$9,"Needs Review") -> Male | D5: =VALUE('01_raw_data'!D8) -> 28 | E5: =IF(OR('01_raw_data'!E8="", LOWER(TRIM('01_raw_data'!E8))="not available"), "Missing", '01_raw_data'!E8) -> 12-01-1997 | F5: =IF(OR(E5="",LOWER(TRIM(E5))="not available"),"Missing",IF(ISNUMBER(E5),"Valid","Needs Review")) -> Needs Review | G5: =_xlfn.XLOOKUP(UPPER(TRIM('01_raw_data'!F8)),'04_departments'!A8:A63,'04_departments'!C8:C63,"Needs Review") -> Legal | H5: =_xlfn.XLOOKUP('01_clean_data'!G5, '04_departments'!$C$5:$C$60,'04_departments'!$D$5:$D$60,"Needs Review") -> Risk & Compliance | I5: =PROPER(TRIM('01_raw_data'!H8)) -> Contracts Analyst | J5: =IFERROR(UPPER('01_raw_data'!I8), "") -> L5 | K5: =IFERROR(UPPER('01_raw_data'!J8), "") -> M011 | L5: =IFERROR(VLOOKUP(K5,'05_manager_mapping'!$A$5:$B$64,2), "Missing") -> Julia Marino | M5: =IFERROR(_xlfn.XLOOKUP('01_raw_data'!L8,'06_location_master'!$B$5:$B$60,'06_location_master'!$C$5:$C$60), "Missing Location") -> Milan | N5: =IFERROR(_xlfn.XLOOKUP(M5,'06_location_master'!$C$5:$C$60,'06_location_master'!$D$5:$D$60), "Missing Country") -> Italy | O5: =IFERROR(_xlfn.XLOOKUP(M5,'06_location_master'!$C$5:$C$60,'06_location_master'!$E$5:$E$60), "Missing State") -> Lombardy | P5: =IFERROR(--'01_raw_data'!O8,"Missing Date") -> 44343 | Q5: =IF(TRIM('01_raw_data'!P8)="","", IFERROR('01_raw_data'!P8, "check")) | R5: =IFERROR(IF(OR(UPPER(TRIM('01_raw_data'!Q8))="A",UPPER(TRIM('01_raw_data'!Q8)="ACTVE"),UPPER(TRIM('01_raw_data'!Q8))="ACTIVE"), "Active", IF(OR(UPPER(TRIM('01_raw_data'!Q8)="INACTIVE"),UPPER(TRIM('01_raw_data'!Q8))="INACTVE"),"Inactive",IF(OR(UPPER(TRIM('01_raw_data'!Q8))="EXITED"), "Exited", IF(OR(UPPER(TRIM('01_raw_data'!Q8))="TERMINATED"), "Terminated", IF(OR(UPPER(TRIM('01_raw_data'!Q8))="LEFT"),"Left",IF(OR(UPPER(TRIM('01_raw_data'!Q8))="RESIGNED"),"Resigned")))))),"Check") -> Active | S5: =IFERROR(IF(VALUE('01_raw_data'!R8)>0,VALUE('01_raw_data'!R8),"Check"),"Check") -> 118000 | T5: =IFERROR(IF(VALUE('01_raw_data'!S8)>0, VALUE('01_raw_data'!S8), "Check"), "Check") -> 1200 | U5: =IFERROR(VLOOKUP(UPPER(TRIM('01_raw_data'!T8)),'07_performance_master'!$A$5:$B$14,2,FALSE),"Check") -> 1 | V5: =IFERROR(IF(VALUE('01_raw_data'!U8)>0,VALUE('01_raw_data'!U8),"Check"),"Check") -> 27 | W5: =IFERROR(IF(VALUE('01_raw_data'!V8)>=0, VALUE('01_raw_data'!V8), "Check"), "Check") -> 20 | X5: =IFERROR(IF(VALUE('01_raw_data'!W8)>=0, VALUE('01_raw_data'!W8),"Check"), "Check") -> 27 | Y5: =IFERROR(IF(AND(VALUE('01_raw_data'!X8)>=0, VALUE('01_raw_data'!X8)<=100), VALUE('01_raw_data'!X8), "Check"), "Check") -> 26 | Z5: =IFERROR(IF(OR(UPPER(TRIM('01_raw_data'!Y8))="YES", UPPER(TRIM('01_raw_data'!Y8))="PROMOTED"),"Promoted", IF(OR(UPPER(TRIM('01_raw_data'!Y8))="NO",UPPER(TRIM('01_raw_data'!Y8))="NOT PROMOTED"), "Not Promoted", "Check")),"Check") -> Not Promoted | AA5: =IFERROR(PROPER(TRIM('01_raw_data'!Z8)), "") -> Bachelor'S | AB5: =IFERROR(PROPER(TRIM('01_raw_data'!AA8)),"") -> Company Careers Page | AC5: =IFERROR(IF(UPPER(TRIM('01_raw_data'!AB8))="HYBRID","Hybrid",IF(OR(UPPER(TRIM('01_raw_data'!AB8))="REMOTE",UPPER(TRIM('01_raw_data'!AB8))="WFH",UPPER(TRIM('01_raw_data'!AB8))="WORK FROM HOME"),"Remote",IF(OR(UPPER(TRIM('01_raw_data'!AB8))="ONSITE",UPPER(TRIM('01_raw_data'!AB8))="ON-SITE",UPPER(TRIM('01_raw_data'!AB8))="OFFICE"),"Office"))),"Check") -> Hybrid | AD5: =IFERROR(VLOOKUP(UPPER(TRIM('01_raw_data'!AC8)),'09_cost_center'!$A$5:$E$19,1,FALSE), "Check") -> EU-CC501 | AE5: =IFERROR(IF(OR(UPPER(TRIM('01_raw_data'!AD8))="CONTRACT", UPPER(TRIM('01_raw_data'!AD8))="CONTRACTOR"), "Contract", IF(OR(PROPER(TRIM('01_raw_data'!AD8))="FTE", UPPER(TRIM('01_raw_data'!AD8))="FULL TIME", UPPER(TRIM('01_raw_data'!AD8))="FULL-TIME"), "Full Time", IF(OR(UPPER(TRIM('01_raw_data'!AD8))="INTERN", UPPER(TRIM('01_raw_data'!AD8))="INTERNSHIP"), "Intern", IF(OR(UPPER(TRIM('01_raw_data'!AD8))="PART TIME", UPPER(TRIM('01_raw_data'!AD8))="PART-TIME"), "Part Time")))), "Check") -> Contract | AF5: =IFERROR(IF(AND(VALUE('01_raw_data'!AE8)>=0,VALUE('01_raw_data'!AE8)<=100), VALUE('01_raw_data'!AE8), "Check"), "Check") -> 24.9
A6: ="E"&TEXT(VALUE(SUBSTITUTE(UPPER(TRIM('01_raw_data'!A9)),"E","")),"0000") -> E0005 | B6: =IF('01_raw_data'!B9="", "", PROPER(TRIM('01_raw_data'!B9))) -> Kacper Brown | C6: =_xlfn.XLOOKUP(PROPER(TRIM('01_raw_data'!C9)),'03_lookups'!$A$4:$A$9,'03_lookups'!$B$4:$B$9,"Needs Review") -> Male | D6: =VALUE('01_raw_data'!D9) -> 38 | E6: =IF(OR('01_raw_data'!E9="", LOWER(TRIM('01_raw_data'!E9))="not available"), "Missing", '01_raw_data'!E9) -> 32217 | F6: =IF(OR(E6="",LOWER(TRIM(E6))="not available"),"Missing",IF(ISNUMBER(E6),"Valid","Needs Review")) -> Valid | G6: =_xlfn.XLOOKUP(UPPER(TRIM('01_raw_data'!F9)),'04_departments'!A9:A64,'04_departments'!C9:C64,"Needs Review") -> Marketing | H6: =_xlfn.XLOOKUP('01_clean_data'!G6, '04_departments'!$C$5:$C$60,'04_departments'!$D$5:$D$60,"Needs Review") -> Revenue | I6: =PROPER(TRIM('01_raw_data'!H9)) -> Marketing Executive | J6: =IFERROR(UPPER('01_raw_data'!I9), "") -> L6 | K6: =IFERROR(UPPER('01_raw_data'!J9), "") -> M006 | L6: =IFERROR(VLOOKUP(K6,'05_manager_mapping'!$A$5:$B$64,2), "Missing") -> Aleksander Fischer | M6: =IFERROR(_xlfn.XLOOKUP('01_raw_data'!L9,'06_location_master'!$B$5:$B$60,'06_location_master'!$C$5:$C$60), "Missing Location") -> Madrid | N6: =IFERROR(_xlfn.XLOOKUP(M6,'06_location_master'!$C$5:$C$60,'06_location_master'!$D$5:$D$60), "Missing Country") -> Spain | O6: =IFERROR(_xlfn.XLOOKUP(M6,'06_location_master'!$C$5:$C$60,'06_location_master'!$E$5:$E$60), "Missing State") -> Community of Madrid | P6: =IFERROR(--'01_raw_data'!O9,"Missing Date") -> 43996 | Q6: =IF(TRIM('01_raw_data'!P9)="","", IFERROR('01_raw_data'!P9, "check")) | R6: =IFERROR(IF(OR(UPPER(TRIM('01_raw_data'!Q9))="A",UPPER(TRIM('01_raw_data'!Q9)="ACTVE"),UPPER(TRIM('01_raw_data'!Q9))="ACTIVE"), "Active", IF(OR(UPPER(TRIM('01_raw_data'!Q9)="INACTIVE"),UPPER(TRIM('01_raw_data'!Q9))="INACTVE"),"Inactive",IF(OR(UPPER(TRIM('01_raw_data'!Q9))="EXITED"), "Exited", IF(OR(UPPER(TRIM('01_raw_data'!Q9))="TERMINATED"), "Terminated", IF(OR(UPPER(TRIM('01_raw_data'!Q9))="LEFT"),"Left",IF(OR(UPPER(TRIM('01_raw_data'!Q9))="RESIGNED"),"Resigned")))))),"Check") -> Active | S6: =IFERROR(IF(VALUE('01_raw_data'!R9)>0,VALUE('01_raw_data'!R9),"Check"),"Check") -> 157000 | T6: =IFERROR(IF(VALUE('01_raw_data'!S9)>0, VALUE('01_raw_data'!S9), "Check"), "Check") -> 9400 | U6: =IFERROR(VLOOKUP(UPPER(TRIM('01_raw_data'!T9)),'07_performance_master'!$A$5:$B$14,2,FALSE),"Check") -> 3 | V6: =IFERROR(IF(VALUE('01_raw_data'!U9)>0,VALUE('01_raw_data'!U9),"Check"),"Check") -> 15 | W6: =IFERROR(IF(VALUE('01_raw_data'!V9)>=0, VALUE('01_raw_data'!V9), "Check"), "Check") -> 12 | X6: =IFERROR(IF(VALUE('01_raw_data'!W9)>=0, VALUE('01_raw_data'!W9),"Check"), "Check") -> 11 | Y6: =IFERROR(IF(AND(VALUE('01_raw_data'!X9)>=0, VALUE('01_raw_data'!X9)<=100), VALUE('01_raw_data'!X9), "Check"), "Check") -> 63 | Z6: =IFERROR(IF(OR(UPPER(TRIM('01_raw_data'!Y9))="YES", UPPER(TRIM('01_raw_data'!Y9))="PROMOTED"),"Promoted", IF(OR(UPPER(TRIM('01_raw_data'!Y9))="NO",UPPER(TRIM('01_raw_data'!Y9))="NOT PROMOTED"), "Not Promoted", "Check")),"Check") -> Not Promoted | AA6: =IFERROR(PROPER(TRIM('01_raw_data'!Z9)), "") -> Mba | AB6: =IFERROR(PROPER(TRIM('01_raw_data'!AA9)),"") -> University Hiring | AC6: =IFERROR(IF(UPPER(TRIM('01_raw_data'!AB9))="HYBRID","Hybrid",IF(OR(UPPER(TRIM('01_raw_data'!AB9))="REMOTE",UPPER(TRIM('01_raw_data'!AB9))="WFH",UPPER(TRIM('01_raw_data'!AB9))="WORK FROM HOME"),"Remote",IF(OR(UPPER(TRIM('01_raw_data'!AB9))="ONSITE",UPPER(TRIM('01_raw_data'!AB9))="ON-SITE",UPPER(TRIM('01_raw_data'!AB9))="OFFICE"),"Office"))),"Check") -> Hybrid | AD6: =IFERROR(VLOOKUP(UPPER(TRIM('01_raw_data'!AC9)),'09_cost_center'!$A$5:$E$19,1,FALSE), "Check") -> EU-CC203 | AE6: =IFERROR(IF(OR(UPPER(TRIM('01_raw_data'!AD9))="CONTRACT", UPPER(TRIM('01_raw_data'!AD9))="CONTRACTOR"), "Contract", IF(OR(PROPER(TRIM('01_raw_data'!AD9))="FTE", UPPER(TRIM('01_raw_data'!AD9))="FULL TIME", UPPER(TRIM('01_raw_data'!AD9))="FULL-TIME"), "Full Time", IF(OR(UPPER(TRIM('01_raw_data'!AD9))="INTERN", UPPER(TRIM('01_raw_data'!AD9))="INTERNSHIP"), "Intern", IF(OR(UPPER(TRIM('01_raw_data'!AD9))="PART TIME", UPPER(TRIM('01_raw_data'!AD9))="PART-TIME"), "Part Time")))), "Check") -> Full Time | AF6: =IFERROR(IF(AND(VALUE('01_raw_data'!AE9)>=0,VALUE('01_raw_data'!AE9)<=100), VALUE('01_raw_data'!AE9), "Check"), "Check") -> 57.3
A7: ="E"&TEXT(VALUE(SUBSTITUTE(UPPER(TRIM('01_raw_data'!A10)),"E","")),"0000") -> E0006 | B7: =IF('01_raw_data'!B10="", "", PROPER(TRIM('01_raw_data'!B10))) -> Kacper Gustafsson | C7: =_xlfn.XLOOKUP(PROPER(TRIM('01_raw_data'!C10)),'03_lookups'!$A$4:$A$9,'03_lookups'!$B$4:$B$9,"Needs Review") -> Male | D7: =VALUE('01_raw_data'!D10) -> 29 | E7: =IF(OR('01_raw_data'!E10="", LOWER(TRIM('01_raw_data'!E10))="not available"), "Missing", '01_raw_data'!E10) -> Missing | F7: =IF(OR(E7="",LOWER(TRIM(E7))="not available"),"Missing",IF(ISNUMBER(E7),"Valid","Needs Review")) -> Needs Review | G7: =_xlfn.XLOOKUP(UPPER(TRIM('01_raw_data'!F10)),'04_departments'!A10:A65,'04_departments'!C10:C65,"Needs Review") -> Customer Success | H7: =_xlfn.XLOOKUP('01_clean_data'!G7, '04_departments'!$C$5:$C$60,'04_departments'!$D$5:$D$60,"Needs Review") -> Revenue | I7: =PROPER(TRIM('01_raw_data'!H10)) -> Client Success Associate | J7: =IFERROR(UPPER('01_raw_data'!I10), "") -> L3 | K7: =IFERROR(UPPER('01_raw_data'!J10), "") -> M054 | L7: =IFERROR(VLOOKUP(K7,'05_manager_mapping'!$A$5:$B$64,2), "Missing") -> Isla Eriksson | M7: =IFERROR(_xlfn.XLOOKUP('01_raw_data'!L10,'06_location_master'!$B$5:$B$60,'06_location_master'!$C$5:$C$60), "Missing Location") -> Stockholm | N7: =IFERROR(_xlfn.XLOOKUP(M7,'06_location_master'!$C$5:$C$60,'06_location_master'!$D$5:$D$60), "Missing Country") -> Sweden | O7: =IFERROR(_xlfn.XLOOKUP(M7,'06_location_master'!$C$5:$C$60,'06_location_master'!$E$5:$E$60), "Missing State") -> Stockholm County | P7: =IFERROR(--'01_raw_data'!O10,"Missing Date") -> 44665 | Q7: =IF(TRIM('01_raw_data'!P10)="","", IFERROR('01_raw_data'!P10, "check")) | R7: =IFERROR(IF(OR(UPPER(TRIM('01_raw_data'!Q10))="A",UPPER(TRIM('01_raw_data'!Q10)="ACTVE"),UPPER(TRIM('01_raw_data'!Q10))="ACTIVE"), "Active", IF(OR(UPPER(TRIM('01_raw_data'!Q10)="INACTIVE"),UPPER(TRIM('01_raw_data'!Q10))="INACTVE"),"Inactive",IF(OR(UPPER(TRIM('01_raw_data'!Q10))="EXITED"), "Exited", IF(OR(UPPER(TRIM('01_raw_data'!Q10))="TERMINATED"), "Terminated", IF(OR(UPPER(TRIM('01_raw_data'!Q10))="LEFT"),"Left",IF(OR(UPPER(TRIM('01_raw_data'!Q10))="RESIGNED"),"Resigned")))))),"Check") -> Active | S7: =IFERROR(IF(VALUE('01_raw_data'!R10)>0,VALUE('01_raw_data'!R10),"Check"),"Check") -> 79000 | T7: =IFERROR(IF(VALUE('01_raw_data'!S10)>0, VALUE('01_raw_data'!S10), "Check"), "Check") -> 7100 | U7: =IFERROR(VLOOKUP(UPPER(TRIM('01_raw_data'!T10)),'07_performance_master'!$A$5:$B$14,2,FALSE),"Check") -> 4 | V7: =IFERROR(IF(VALUE('01_raw_data'!U10)>0,VALUE('01_raw_data'!U10),"Check"),"Check") -> Check | W7: =IFERROR(IF(VALUE('01_raw_data'!V10)>=0, VALUE('01_raw_data'!V10), "Check"), "Check") -> 23 | X7: =IFERROR(IF(VALUE('01_raw_data'!W10)>=0, VALUE('01_raw_data'!W10),"Check"), "Check") -> 0 | Y7: =IFERROR(IF(AND(VALUE('01_raw_data'!X10)>=0, VALUE('01_raw_data'!X10)<=100), VALUE('01_raw_data'!X10), "Check"), "Check") -> 84 | Z7: =IFERROR(IF(OR(UPPER(TRIM('01_raw_data'!Y10))="YES", UPPER(TRIM('01_raw_data'!Y10))="PROMOTED"),"Promoted", IF(OR(UPPER(TRIM('01_raw_data'!Y10))="NO",UPPER(TRIM('01_raw_data'!Y10))="NOT PROMOTED"), "Not Promoted", "Check")),"Check") -> Not Promoted | AA7: =IFERROR(PROPER(TRIM('01_raw_data'!Z10)), "") -> Bachelor'S | AB7: =IFERROR(PROPER(TRIM('01_raw_data'!AA10)),"") -> Agency | AC7: =IFERROR(IF(UPPER(TRIM('01_raw_data'!AB10))="HYBRID","Hybrid",IF(OR(UPPER(TRIM('01_raw_data'!AB10))="REMOTE",UPPER(TRIM('01_raw_data'!AB10))="WFH",UPPER(TRIM('01_raw_data'!AB10))="WORK FROM HOME"),"Remote",IF(OR(UPPER(TRIM('01_raw_data'!AB10))="ONSITE",UPPER(TRIM('01_raw_data'!AB10))="ON-SITE",UPPER(TRIM('01_raw_data'!AB10))="OFFICE"),"Office"))),"Check") -> Hybrid | AD7: =IFERROR(VLOOKUP(UPPER(TRIM('01_raw_data'!AC10)),'09_cost_center'!$A$5:$E$19,1,FALSE), "Check") -> EU-CC202 | AE7: =IFERROR(IF(OR(UPPER(TRIM('01_raw_data'!AD10))="CONTRACT", UPPER(TRIM('01_raw_data'!AD10))="CONTRACTOR"), "Contract", IF(OR(PROPER(TRIM('01_raw_data'!AD10))="FTE", UPPER(TRIM('01_raw_data'!AD10))="FULL TIME", UPPER(TRIM('01_raw_data'!AD10))="FULL-TIME"), "Full Time", IF(OR(UPPER(TRIM('01_raw_data'!AD10))="INTERN", UPPER(TRIM('01_raw_data'!AD10))="INTERNSHIP"), "Intern", IF(OR(UPPER(TRIM('01_raw_data'!AD10))="PART TIME", UPPER(TRIM('01_raw_data'!AD10))="PART-TIME"), "Part Time")))), "Check") -> Full Time | AF7: =IFERROR(IF(AND(VALUE('01_raw_data'!AE10)>=0,VALUE('01_raw_data'!AE10)<=100), VALUE('01_raw_data'!AE10), "Check"), "Check") -> 83.2
A8: ="E"&TEXT(VALUE(SUBSTITUTE(UPPER(TRIM('01_raw_data'!A11)),"E","")),"0000") -> E0007 | B8: =IF('01_raw_data'!B11="", "", PROPER(TRIM('01_raw_data'!B11))) -> Ines Martinez | C8: =_xlfn.XLOOKUP(PROPER(TRIM('01_raw_data'!C11)),'03_lookups'!$A$4:$A$9,'03_lookups'!$B$4:$B$9,"Needs Review") -> Male | D8: =VALUE('01_raw_data'!D11) -> 32 | E8: =IF(OR('01_raw_data'!E11="", LOWER(TRIM('01_raw_data'!E11))="not available"), "Missing", '01_raw_data'!E11) -> 34162 | F8: =IF(OR(E8="",LOWER(TRIM(E8))="not available"),"Missing",IF(ISNUMBER(E8),"Valid","Needs Review")) -> Valid | G8: =_xlfn.XLOOKUP(UPPER(TRIM('01_raw_data'!F11)),'04_departments'!A11:A66,'04_departments'!C11:C66,"Needs Review") -> Needs Review | H8: =_xlfn.XLOOKUP('01_clean_data'!G8, '04_departments'!$C$5:$C$60,'04_departments'!$D$5:$D$60,"Needs Review") -> Needs Review | I8: =PROPER(TRIM('01_raw_data'!H11)) -> Engineering Lead | J8: =IFERROR(UPPER('01_raw_data'!I11), "") -> L3 | K8: =IFERROR(UPPER('01_raw_data'!J11), "") -> M048 | L8: =IFERROR(VLOOKUP(K8,'05_manager_mapping'!$A$5:$B$64,2), "Missing") -> Jack Schmidt | M8: =IFERROR(_xlfn.XLOOKUP('01_raw_data'!L11,'06_location_master'!$B$5:$B$60,'06_location_master'!$C$5:$C$60), "Missing Location") -> Hamburg | N8: =IFERROR(_xlfn.XLOOKUP(M8,'06_location_master'!$C$5:$C$60,'06_location_master'!$D$5:$D$60), "Missing Country") -> Germany | O8: =IFERROR(_xlfn.XLOOKUP(M8,'06_location_master'!$C$5:$C$60,'06_location_master'!$E$5:$E$60), "Missing State") -> Hamburg | P8: =IFERROR(--'01_raw_data'!O11,"Missing Date") -> 45404 | Q8: =IF(TRIM('01_raw_data'!P11)="","", IFERROR('01_raw_data'!P11, "check")) | R8: =IFERROR(IF(OR(UPPER(TRIM('01_raw_data'!Q11))="A",UPPER(TRIM('01_raw_data'!Q11)="ACTVE"),UPPER(TRIM('01_raw_data'!Q11))="ACTIVE"), "Active", IF(OR(UPPER(TRIM('01_raw_data'!Q11)="INACTIVE"),UPPER(TRIM('01_raw_data'!Q11))="INACTVE"),"Inactive",IF(OR(UPPER(TRIM('01_raw_data'!Q11))="EXITED"), "Exited", IF(OR(UPPER(TRIM('01_raw_data'!Q11))="TERMINATED"), "Terminated", IF(OR(UPPER(TRIM('01_raw_data'!Q11))="LEFT"),"Left",IF(OR(UPPER(TRIM('01_raw_data'!Q11))="RESIGNED"),"Resigned")))))),"Check") -> Active | S8: =IFERROR(IF(VALUE('01_raw_data'!R11)>0,VALUE('01_raw_data'!R11),"Check"),"Check") -> 85000 | T8: =IFERROR(IF(VALUE('01_raw_data'!S11)>0, VALUE('01_raw_data'!S11), "Check"), "Check") -> 1700 | U8: =IFERROR(VLOOKUP(UPPER(TRIM('01_raw_data'!T11)),'07_performance_master'!$A$5:$B$14,2,FALSE),"Check") -> 2 | V8: =IFERROR(IF(VALUE('01_raw_data'!U11)>0,VALUE('01_raw_data'!U11),"Check"),"Check") -> 57 | W8: =IFERROR(IF(VALUE('01_raw_data'!V11)>=0, VALUE('01_raw_data'!V11), "Check"), "Check") -> 20 | X8: =IFERROR(IF(VALUE('01_raw_data'!W11)>=0, VALUE('01_raw_data'!W11),"Check"), "Check") -> 0 | Y8: =IFERROR(IF(AND(VALUE('01_raw_data'!X11)>=0, VALUE('01_raw_data'!X11)<=100), VALUE('01_raw_data'!X11), "Check"), "Check") -> 46 | Z8: =IFERROR(IF(OR(UPPER(TRIM('01_raw_data'!Y11))="YES", UPPER(TRIM('01_raw_data'!Y11))="PROMOTED"),"Promoted", IF(OR(UPPER(TRIM('01_raw_data'!Y11))="NO",UPPER(TRIM('01_raw_data'!Y11))="NOT PROMOTED"), "Not Promoted", "Check")),"Check") -> Not Promoted | AA8: =IFERROR(PROPER(TRIM('01_raw_data'!Z11)), "") -> Bachelor'S | AB8: =IFERROR(PROPER(TRIM('01_raw_data'!AA11)),"") -> University Hiring | AC8: =IFERROR(IF(UPPER(TRIM('01_raw_data'!AB11))="HYBRID","Hybrid",IF(OR(UPPER(TRIM('01_raw_data'!AB11))="REMOTE",UPPER(TRIM('01_raw_data'!AB11))="WFH",UPPER(TRIM('01_raw_data'!AB11))="WORK FROM HOME"),"Remote",IF(OR(UPPER(TRIM('01_raw_data'!AB11))="ONSITE",UPPER(TRIM('01_raw_data'!AB11))="ON-SITE",UPPER(TRIM('01_raw_data'!AB11))="OFFICE"),"Office"))),"Check") -> Hybrid | AD8: =IFERROR(VLOOKUP(UPPER(TRIM('01_raw_data'!AC11)),'09_cost_center'!$A$5:$E$19,1,FALSE), "Check") -> EU-CC101 | AE8: =IFERROR(IF(OR(UPPER(TRIM('01_raw_data'!AD11))="CONTRACT", UPPER(TRIM('01_raw_data'!AD11))="CONTRACTOR"), "Contract", IF(OR(PROPER(TRIM('01_raw_data'!AD11))="FTE", UPPER(TRIM('01_raw_data'!AD11))="FULL TIME", UPPER(TRIM('01_raw_data'!AD11))="FULL-TIME"), "Full Time", IF(OR(UPPER(TRIM('01_raw_data'!AD11))="INTERN", UPPER(TRIM('01_raw_data'!AD11))="INTERNSHIP"), "Intern", IF(OR(UPPER(TRIM('01_raw_data'!AD11))="PART TIME", UPPER(TRIM('01_raw_data'!AD11))="PART-TIME"), "Part Time")))), "Check") -> Full Time | AF8: =IFERROR(IF(AND(VALUE('01_raw_data'!AE11)>=0,VALUE('01_raw_data'!AE11)<=100), VALUE('01_raw_data'!AE11), "Check"), "Check") -> 54.1
A9: ="E"&TEXT(VALUE(SUBSTITUTE(UPPER(TRIM('01_raw_data'!A12)),"E","")),"0000") -> E0008 | B9: =IF('01_raw_data'!B12="", "", PROPER(TRIM('01_raw_data'!B12))) -> Alessandro Jansen | C9: =_xlfn.XLOOKUP(PROPER(TRIM('01_raw_data'!C12)),'03_lookups'!$A$4:$A$9,'03_lookups'!$B$4:$B$9,"Needs Review") -> Male | D9: =VALUE('01_raw_data'!D12) -> 22 | E9: =IF(OR('01_raw_data'!E12="", LOWER(TRIM('01_raw_data'!E12))="not available"), "Missing", '01_raw_data'!E12) -> 38098 | F9: =IF(OR(E9="",LOWER(TRIM(E9))="not available"),"Missing",IF(ISNUMBER(E9),"Valid","Needs Review")) -> Valid | G9: =_xlfn.XLOOKUP(UPPER(TRIM('01_raw_data'!F12)),'04_departments'!A12:A67,'04_departments'!C12:C67,"Needs Review") -> Operations | H9: =_xlfn.XLOOKUP('01_clean_data'!G9, '04_departments'!$C$5:$C$60,'04_departments'!$D$5:$D$60,"Needs Review") -> Operations | I9: =PROPER(TRIM('01_raw_data'!H12)) -> Workforce Planner | J9: =IFERROR(UPPER('01_raw_data'!I12), "") -> L2 | K9: =IFERROR(UPPER('01_raw_data'!J12), "") -> M010 | L9: =IFERROR(VLOOKUP(K9,'05_manager_mapping'!$A$5:$B$64,2), "Missing") -> Lotte Muller | M9: =IFERROR(_xlfn.XLOOKUP('01_raw_data'!L12,'06_location_master'!$B$5:$B$60,'06_location_master'!$C$5:$C$60), "Missing Location") -> Eindhoven | N9: =IFERROR(_xlfn.XLOOKUP(M9,'06_location_master'!$C$5:$C$60,'06_location_master'!$D$5:$D$60), "Missing Country") -> Netherlands | O9: =IFERROR(_xlfn.XLOOKUP(M9,'06_location_master'!$C$5:$C$60,'06_location_master'!$E$5:$E$60), "Missing State") -> North Brabant | P9: =IFERROR(--'01_raw_data'!O12,"Missing Date") -> 45703 | Q9: =IF(TRIM('01_raw_data'!P12)="","", IFERROR('01_raw_data'!P12, "check")) -> 01-08-2026 | R9: =IFERROR(IF(OR(UPPER(TRIM('01_raw_data'!Q12))="A",UPPER(TRIM('01_raw_data'!Q12)="ACTVE"),UPPER(TRIM('01_raw_data'!Q12))="ACTIVE"), "Active", IF(OR(UPPER(TRIM('01_raw_data'!Q12)="INACTIVE"),UPPER(TRIM('01_raw_data'!Q12))="INACTVE"),"Inactive",IF(OR(UPPER(TRIM('01_raw_data'!Q12))="EXITED"), "Exited", IF(OR(UPPER(TRIM('01_raw_data'!Q12))="TERMINATED"), "Terminated", IF(OR(UPPER(TRIM('01_raw_data'!Q12))="LEFT"),"Left",IF(OR(UPPER(TRIM('01_raw_data'!Q12))="RESIGNED"),"Resigned")))))),"Check") -> Exited | S9: =IFERROR(IF(VALUE('01_raw_data'!R12)>0,VALUE('01_raw_data'!R12),"Check"),"Check") -> 56000 | T9: =IFERROR(IF(VALUE('01_raw_data'!S12)>0, VALUE('01_raw_data'!S12), "Check"), "Check") -> 7800 | U9: =IFERROR(VLOOKUP(UPPER(TRIM('01_raw_data'!T12)),'07_performance_master'!$A$5:$B$14,2,FALSE),"Check") -> 5 | V9: =IFERROR(IF(VALUE('01_raw_data'!U12)>0,VALUE('01_raw_data'!U12),"Check"),"Check") -> 48 | W9: =IFERROR(IF(VALUE('01_raw_data'!V12)>=0, VALUE('01_raw_data'!V12), "Check"), "Check") -> 10 | X9: =IFERROR(IF(VALUE('01_raw_data'!W12)>=0, VALUE('01_raw_data'!W12),"Check"), "Check") -> 1 | Y9: =IFERROR(IF(AND(VALUE('01_raw_data'!X12)>=0, VALUE('01_raw_data'!X12)<=100), VALUE('01_raw_data'!X12), "Check"), "Check") -> 57 | Z9: =IFERROR(IF(OR(UPPER(TRIM('01_raw_data'!Y12))="YES", UPPER(TRIM('01_raw_data'!Y12))="PROMOTED"),"Promoted", IF(OR(UPPER(TRIM('01_raw_data'!Y12))="NO",UPPER(TRIM('01_raw_data'!Y12))="NOT PROMOTED"), "Not Promoted", "Check")),"Check") -> Not Promoted | AA9: =IFERROR(PROPER(TRIM('01_raw_data'!Z12)), "") -> Bachelor'S | AB9: =IFERROR(PROPER(TRIM('01_raw_data'!AA12)),"") -> European Job Board | AC9: =IFERROR(IF(UPPER(TRIM('01_raw_data'!AB12))="HYBRID","Hybrid",IF(OR(UPPER(TRIM('01_raw_data'!AB12))="REMOTE",UPPER(TRIM('01_raw_data'!AB12))="WFH",UPPER(TRIM('01_raw_data'!AB12))="WORK FROM HOME"),"Remote",IF(OR(UPPER(TRIM('01_raw_data'!AB12))="ONSITE",UPPER(TRIM('01_raw_data'!AB12))="ON-SITE",UPPER(TRIM('01_raw_data'!AB12))="OFFICE"),"Office"))),"Check") -> Remote | AD9: =IFERROR(VLOOKUP(UPPER(TRIM('01_raw_data'!AC12)),'09_cost_center'!$A$5:$E$19,1,FALSE), "Check") -> EU-CC401 | AE9: =IFERROR(IF(OR(UPPER(TRIM('01_raw_data'!AD12))="CONTRACT", UPPER(TRIM('01_raw_data'!AD12))="CONTRACTOR"), "Contract", IF(OR(PROPER(TRIM('01_raw_data'!AD12))="FTE", UPPER(TRIM('01_raw_data'!AD12))="FULL TIME", UPPER(TRIM('01_raw_data'!AD12))="FULL-TIME"), "Full Time", IF(OR(UPPER(TRIM('01_raw_data'!AD12))="INTERN", UPPER(TRIM('01_raw_data'!AD12))="INTERNSHIP"), "Intern", IF(OR(UPPER(TRIM('01_raw_data'!AD12))="PART TIME", UPPER(TRIM('01_raw_data'!AD12))="PART-TIME"), "Part Time")))), "Check") -> Full Time | AF9: =IFERROR(IF(AND(VALUE('01_raw_data'!AE12)>=0,VALUE('01_raw_data'!AE12)<=100), VALUE('01_raw_data'!AE12), "Check"), "Check") -> 84.5
A10: ="E"&TEXT(VALUE(SUBSTITUTE(UPPER(TRIM('01_raw_data'!A13)),"E","")),"0000") -> E0009 | B10: =IF('01_raw_data'!B13="", "", PROPER(TRIM('01_raw_data'!B13))) -> Javier Ricci | C10: =_xlfn.XLOOKUP(PROPER(TRIM('01_raw_data'!C13)),'03_lookups'!$A$4:$A$9,'03_lookups'!$B$4:$B$9,"Needs Review") -> Male | D10: =VALUE('01_raw_data'!D13) -> 37 | E10: =IF(OR('01_raw_data'!E13="", LOWER(TRIM('01_raw_data'!E13))="not available"), "Missing", '01_raw_data'!E13) -> 32347 | F10: =IF(OR(E10="",LOWER(TRIM(E10))="not available"),"Missing",IF(ISNUMBER(E10),"Valid","Needs Review")) -> Valid | G10: =_xlfn.XLOOKUP(UPPER(TRIM('01_raw_data'!F13)),'04_departments'!A13:A68,'04_departments'!C13:C68,"Needs Review") -> Data & Analytics | H10: =_xlfn.XLOOKUP('01_clean_data'!G10, '04_departments'!$C$5:$C$60,'04_departments'!$D$5:$D$60,"Needs Review") -> Data & AI | I10: =PROPER(TRIM('01_raw_data'!H13)) -> Data Scientist | J10: =IFERROR(UPPER('01_raw_data'!I13), "") -> L4 | K10: =IFERROR(UPPER('01_raw_data'!J13), "") -> M020 | L10: =IFERROR(VLOOKUP(K10,'05_manager_mapping'!$A$5:$B$64,2), "Missing") -> Alessandro Lewandowski | M10: =IFERROR(_xlfn.XLOOKUP('01_raw_data'!L13,'06_location_master'!$B$5:$B$60,'06_location_master'!$C$5:$C$60), "Missing Location") -> Munich | N10: =IFERROR(_xlfn.XLOOKUP(M10,'06_location_master'!$C$5:$C$60,'06_location_master'!$D$5:$D$60), "Missing Country") -> Germany | O10: =IFERROR(_xlfn.XLOOKUP(M10,'06_location_master'!$C$5:$C$60,'06_location_master'!$E$5:$E$60), "Missing State") -> Bavaria | P10: =IFERROR(--'01_raw_data'!O13,"Missing Date") -> 42863 | Q10: =IF(TRIM('01_raw_data'!P13)="","", IFERROR('01_raw_data'!P13, "check")) | R10: =IFERROR(IF(OR(UPPER(TRIM('01_raw_data'!Q13))="A",UPPER(TRIM('01_raw_data'!Q13)="ACTVE"),UPPER(TRIM('01_raw_data'!Q13))="ACTIVE"), "Active", IF(OR(UPPER(TRIM('01_raw_data'!Q13)="INACTIVE"),UPPER(TRIM('01_raw_data'!Q13))="INACTVE"),"Inactive",IF(OR(UPPER(TRIM('01_raw_data'!Q13))="EXITED"), "Exited", IF(OR(UPPER(TRIM('01_raw_data'!Q13))="TERMINATED"), "Terminated", IF(OR(UPPER(TRIM('01_raw_data'!Q13))="LEFT"),"Left",IF(OR(UPPER(TRIM('01_raw_data'!Q13))="RESIGNED"),"Resigned")))))),"Check") -> Active | S10: =IFERROR(IF(VALUE('01_raw_data'!R13)>0,VALUE('01_raw_data'!R13),"Check"),"Check") -> 109000 | T10: =IFERROR(IF(VALUE('01_raw_data'!S13)>0, VALUE('01_raw_data'!S13), "Check"), "Check") -> 5400 | U10: =IFERROR(VLOOKUP(UPPER(TRIM('01_raw_data'!T13)),'07_performance_master'!$A$5:$B$14,2,FALSE),"Check") -> 3 | V10: =IFERROR(IF(VALUE('01_raw_data'!U13)>0,VALUE('01_raw_data'!U13),"Check"),"Check") -> 29 | W10: =IFERROR(IF(VALUE('01_raw_data'!V13)>=0, VALUE('01_raw_data'!V13), "Check"), "Check") -> 18 | X10: =IFERROR(IF(VALUE('01_raw_data'!W13)>=0, VALUE('01_raw_data'!W13),"Check"), "Check") -> 7 | Y10: =IFERROR(IF(AND(VALUE('01_raw_data'!X13)>=0, VALUE('01_raw_data'!X13)<=100), VALUE('01_raw_data'!X13), "Check"), "Check") -> 47 | Z10: =IFERROR(IF(OR(UPPER(TRIM('01_raw_data'!Y13))="YES", UPPER(TRIM('01_raw_data'!Y13))="PROMOTED"),"Promoted", IF(OR(UPPER(TRIM('01_raw_data'!Y13))="NO",UPPER(TRIM('01_raw_data'!Y13))="NOT PROMOTED"), "Not Promoted", "Check")),"Check") -> Not Promoted | AA10: =IFERROR(PROPER(TRIM('01_raw_data'!Z13)), "") -> Diploma | AB10: =IFERROR(PROPER(TRIM('01_raw_data'!AA13)),"") -> Company Careers Page | AC10: =IFERROR(IF(UPPER(TRIM('01_raw_data'!AB13))="HYBRID","Hybrid",IF(OR(UPPER(TRIM('01_raw_data'!AB13))="REMOTE",UPPER(TRIM('01_raw_data'!AB13))="WFH",UPPER(TRIM('01_raw_data'!AB13))="WORK FROM HOME"),"Remote",IF(OR(UPPER(TRIM('01_raw_data'!AB13))="ONSITE",UPPER(TRIM('01_raw_data'!AB13))="ON-SITE",UPPER(TRIM('01_raw_data'!AB13))="OFFICE"),"Office"))),"Check") -> Hybrid | AD10: =IFERROR(VLOOKUP(UPPER(TRIM('01_raw_data'!AC13)),'09_cost_center'!$A$5:$E$19,1,FALSE), "Check") -> EU-CC103 | AE10: =IFERROR(IF(OR(UPPER(TRIM('01_raw_data'!AD13))="CONTRACT", UPPER(TRIM('01_raw_data'!AD13))="CONTRACTOR"), "Contract", IF(OR(PROPER(TRIM('01_raw_data'!AD13))="FTE", UPPER(TRIM('01_raw_data'!AD13))="FULL TIME", UPPER(TRIM('01_raw_data'!AD13))="FULL-TIME"), "Full Time", IF(OR(UPPER(TRIM('01_raw_data'!AD13))="INTERN", UPPER(TRIM('01_raw_data'!AD13))="INTERNSHIP"), "Intern", IF(OR(UPPER(TRIM('01_raw_data'!AD13))="PART TIME", UPPER(TRIM('01_raw_data'!AD13))="PART-TIME"), "Part Time")))), "Check") -> Full Time | AF10: =IFERROR(IF(AND(VALUE('01_raw_data'!AE13)>=0,VALUE('01_raw_data'!AE13)<=100), VALUE('01_raw_data'!AE13), "Check"), "Check") -> 57.2
